Workbook

Sheet Dashboard
A1: BARRO INDUSTRIES — CLIENT RECORDS & ANALYTICS TRACKER
A2: Kitchen Equipment & Fabrication | As of June 16, 2026 | All amounts in Philippine Peso (₱)
B4: TOTAL CLIENTS | D4: COMPLETED | F4: WON / ONGOING | H4: QUOTATION SENT | J4: DESIGN STAGE
B5: =COUNTA('Client Records'!A3:A200) | D5: =COUNTIF('Client Records'!I3:I200,"Completed") | F5: =COUNTIF('Client Records'!I3:I200,"Won / Ongoing")+COUNTIF('Client Records'!I3:I200,"Ongoing") | H5: =COUNTIF('Client Records'!I3:I200,"Quotation Sent")+COUNTIF('Client Records'!I3:I200,"Proposal Sent") | J5: =COUNTIF('Client Records'!I3:I200,"Design Stage")
B8: TOTAL QUOTED PIPELINE VALUE (₱) | F8: =SUMIF('Client Records'!I3:I200,"Quotation Sent",'Client Records'!H3:H200)+SUMIF('Client Records'!I3:I200,"Proposal Sent",'Client Records'!H3:H200)+SUMIF('Client Records'!I3:I200,"Design Stage",'Client Records'!H3:H200)
B9: TOTAL WON + COMPLETED VALUE (₱) | F9: =SUMIF('Client Records'!I3:I200,"Completed",'Client Records'!H3:H200)+SUMIF('Client Records'!I3:I200,"Won / Ongoing",'Client Records'!H3:H200)+SUMIF('Client Records'!I3:I200,"Ongoing",'Client Records'!H3:H200)
B11: STATUS BREAKDOWN
B12: STATUS | E12: COUNT | F12: % SHARE | G12: TOTAL QUOTED (₱)
B13: Quotation Sent | E13: =COUNTIF('Client Records'!I3:I200,"Quotation Sent") | F13: =IF(E13=0,"-",E13/COUNTA('Client Records'!A3:A200)) | G13: =SUMIF('Client Records'!I3:I200,"Quotation Sent",'Client Records'!H3:H200)
B14: Design Stage | E14: =COUNTIF('Client Records'!I3:I200,"Design Stage") | F14: =IF(E14=0,"-",E14/COUNTA('Client Records'!A3:A200)) | G14: =SUMIF('Client Records'!I3:I200,"Design Stage",'Client Records'!H3:H200)
B15: Proposal Sent | E15: =COUNTIF('Client Records'!I3:I200,"Proposal Sent") | F15: =IF(E15=0,"-",E15/COUNTA('Client Records'!A3:A200)) | G15: =SUMIF('Client Records'!I3:I200,"Proposal Sent",'Client Records'!H3:H200)
B16: Won / Ongoing | E16: =COUNTIF('Client Records'!I3:I200,"Won / Ongoing") | F16: =IF(E16=0,"-",E16/COUNTA('Client Records'!A3:A200)) | G16: =SUMIF('Client Records'!I3:I200,"Won / Ongoing",'Client Records'!H3:H200)
B17: Ongoing | E17: =COUNTIF('Client Records'!I3:I200,"Ongoing") | F17: =IF(E17=0,"-",E17/COUNTA('Client Records'!A3:A200)) | G17: =SUMIF('Client Records'!I3:I200,"Ongoing",'Client Records'!H3:H200)
B18: Completed | E18: =COUNTIF('Client Records'!I3:I200,"Completed") | F18: =IF(E18=0,"-",E18/COUNTA('Client Records'!A3:A200)) | G18: =SUMIF('Client Records'!I3:I200,"Completed",'Client Records'!H3:H200)
B19: Lost / No Response | E19: =COUNTIF('Client Records'!I3:I200,"Lost / No Response") | F19: =IF(E19=0,"-",E19/COUNTA('Client Records'!A3:A200)) | G19: =SUMIF('Client Records'!I3:I200,"Lost / No Response",'Client Records'!H3:H200)
B21: SECTOR BREAKDOWN
B22: SECTOR | F22: COUNT | G22: % SHARE | H22: TOTAL QUOTED (₱)
B23: B2B / Corporate | F23: =COUNTIF('Client Records'!C3:C200,"B2B / Corporate") | G23: =IF(F23=0,"-",F23/COUNTA('Client Records'!A3:A200)) | H23: =SUMIF('Client Records'!C3:C200,"B2B / Corporate",'Client Records'!H3:H200)
B24: Bakery | F24: =COUNTIF('Client Records'!C3:C200,"Bakery") | G24: =IF(F24=0,"-",F24/COUNTA('Client Records'!A3:A200)) | H24: =SUMIF('Client Records'!C3:C200,"Bakery",'Client Records'!H3:H200)
B25: Café | F25: =COUNTIF('Client Records'!C3:C200,"Café") | G25: =IF(F25=0,"-",F25/COUNTA('Client Records'!A3:A200)) | H25: =SUMIF('Client Records'!C3:C200,"Café",'Client Records'!H3:H200)
B26: Education | F26: =COUNTIF('Client Records'!C3:C200,"Education") | G26: =IF(F26=0,"-",F26/COUNTA('Client Records'!A3:A200)) | H26: =SUMIF('Client Records'!C3:C200,"Education",'Client Records'!H3:H200)
B27: Education / Govt | F27: =COUNTIF('Client Records'!C3:C200,"Education / Govt") | G27: =IF(F27=0,"-",F27/COUNTA('Client Records'!A3:A200)) | H27: =SUMIF('Client Records'!C3:C200,"Education / Govt",'Client Records'!H3:H200)
B28: Food Service | F28: =COUNTIF('Client Records'!C3:C200,"Food Service") | G28: =IF(F28=0,"-",F28/COUNTA('Client Records'!A3:A200)) | H28: =SUMIF('Client Records'!C3:C200,"Food Service",'Client Records'!H3:H200)
B29: Hospital | F29: =COUNTIF('Client Records'!C3:C200,"Hospital") | G29: =IF(F29=0,"-",F29/COUNTA('Client Records'!A3:A200)) | H29: =SUMIF('Client Records'!C3:C200,"Hospital",'Client Records'!H3:H200)
B30: Hospitality | F30: =COUNTIF('Client Records'!C3:C200,"Hospitality") | G30: =IF(F30=0,"-",F30/COUNTA('Client Records'!A3:A200)) | H30: =SUMIF('Client Records'!C3:C200,"Hospitality",'Client Records'!H3:H200)
B31: Institutional | F31: =COUNTIF('Client Records'!C3:C200,"Institutional") | G31: =IF(F31=0,"-",F31/COUNTA('Client Records'!A3:A200)) | H31: =SUMIF('Client Records'!C3:C200,"Institutional",'Client Records'!H3:H200)
B32: Restaurant | F32: =COUNTIF('Client Records'!C3:C200,"Restaurant") | G32: =IF(F32=0,"-",F32/COUNTA('Client Records'!A3:A200)) | H32: =SUMIF('Client Records'!C3:C200,"Restaurant",'Client Records'!H3:H200)

Sheet Client Records
A1: BARRO INDUSTRIES — CLIENT RECORDS
A2: # | B2: Client Name | C2: Sector | D2: Location | E2: Contact / Attention | F2: Quotation No. | G2: Date | H2: Project Title / Subject | I2: Quoted Amount (₱) | J2: Status | K2: Documents on File | L2: Remarks / Notes | M2: Date Added | N2: Last Updated
A3: 1 | B3: Aboy Asuncion | C3: Food Service | D3: San Juan, La Union | E3: Mr. Aboy Asuncion | F3: LUON07022025-1 | G3: July 2, 2025 | H3: Supply & Fabrication of Range Hood and Ducting System | I3: 218500 | J3: Quotation Sent | K3: Price Quotation (PDF, JPG)
A4: 2 | B4: Alyssa Flores | C4: Food Service | D4: South Pob., Bucay, Abra | E4: Alyssa Flores | F4: BNOF04092025-2 | G4: April 9, 2025 | H4: Supply & Fabrication of Kitchen Equipment | I4: 290000 | J4: Quotation Sent | K4: Proposal 2025-04-09 (DOCX, PDF)
A5: 3 | B5: Alyssa Marie | C5: Food Service | D5: Baguio City | E5: Alyssa Marie Malasig | F5: ONBG26032025-01 | G5: March 26, 2025 | H5: Table Framing Fabrication | I5: 18500 | J5: Quotation Sent | K5: Price Quotation (DOCX, PDF)
A6: 4 | B6: Andrew Ducas | C6: Food Service | D6: Baguio City | E6: Andrew Ducas | F6: BGON062025-2 | G6: June 30, 2025 | H6: Supply & Fabrication of Kitchen Equipment | I6: 145000 | J6: Quotation Sent | K6: Quotation + Revised Final (multiple versions) | L6: Multiple revisions; Final version issued
A7: 5 | B7: Antonino | C7: Food Service | D7: Urdaneta City, Pangasinan | E7: Antonino | F7: — | G7: — | H7: Kitchen Equipment Supply & Fabrication | I7: See workbook | J7: Quotation Sent | K7: Quotation PDF + XLSM | L7: Amount in XLSM workbook
A8: 6 | B8: Ar. Kryzia Bea (Snooze Coffee) | C8: Café | D8: Leonardwood, Baguio City | E8: Ar. Kryzia Bea | F8: BGON04092025-1 | G8: April 14, 2025 | H8: Supply & Fabrication of Custom Kitchen Setup and Equipment | I8: 595500 | J8: Design Stage | K8: Proposal + Floor Plans (13 revisions) + AI Renders | L8: Detailed kitchen plans; 13 plan revisions on file
A9: 7 | B9: Ar. Richard | C9: Food Service | D9: La Union | E9: Ar. Richard | F9: LUON09272401 | G9: Sep 27, 2024 | H9: Fabrication of Kitchen Equipment | I9: 308000 | J9: Quotation Sent | K9: Price Quotation (DOCX, PDF) + Built-ins List | L9: Includes Casa Carmelo 2.0 built-ins reference
A10: 8 | B10: Arfaz | C10: Food Service | D10: Unknown Location | E10: Arfaz | F10: FB-ONMN060425-1 | G10: June 4, 2025 | H10: Range Hood and Ducting Fabrication | I10: 78000 | J10: Quotation Sent | K10: Price Quotation (DOCX, JPG, PDF) | L10: Estimated total from line items
A11: 9 | B11: Bakers Ph | C11: Bakery | D11: Brgy 44, Laoag City, IN | E11: Bakers Ph | F11: BGON-07182025-1 | G11: July 18, 2025 | H11: SS Preparation Table with Overhead Shelves | I11: 35000 | J11: Quotation Sent | K11: Quotation 2025-07-18 (DOCX, PDF)
A12: 10 | B12: Bethany Hospital | C12: Hospital | D12: San Fernando, La Union | E12: Bethany Hospital | F12: Multiple | G12: Nov 2024 – Feb 2026 | H12: Hospital Kitchen Equipment, Exhaust, Trolleys, Site Works | I12: 1656300 | J12: Completed | K12: Contract + Final Billing Invoice + Multiple Quotations + Job Order + Site Photos | L12: Contract signed; final billing ₱1,656,300; multiple project phases; repeat billings on file
A13: 11 | B13: Brilliant Steel Corp. | C13: B2B / Corporate | D13: N/A | E13: Brilliant Steel Corp. | F13: — | G13: June 2026 | H13: Product Lineup Fabrication Proposal | I13: See workbook | J13: Proposal Sent | K13: Product Lineup Proposal (DOCX) | L13: B2B partnership proposal; no amount specified
A14: 12 | B14: BSBT | C14: Institutional | D14: Baguio City | E14: BSBT | F14: — | G14: 2025 | H14: Kitchen & Bar Setup Fabrication | I14: See workbook | J14: Ongoing | K14: Quotation + MOA + Kitchen Plans + AutoCAD DWG + Design Files | L14: MOA signed; detailed DWG kitchen/bar/gym plans
A15: 13 | B15: BSU | C15: Education | D15: La Trinidad, Benguet | E15: Benguet State Univ. | F15: RFQ01262026-2 | G15: Jan 26, 2026 | H15: Various Equipment Supply | I15: 106000 | J15: Quotation Sent | K15: Quotation (DOCX)
A16: 14 | B16: Candelaria Dist. Hospital | C16: Hospital | D16: Zambales | E16: Candelaria District Hosp. | F16: — | G16: 2025 | H16: Hospital Kitchen Equipment & Fabrication (3 Sections) | I16: 2292000 | J16: Quotation Sent | K16: Proposal + Revised Price Quotation (2 parts DOCX + PDF) | L16: Full hospital kitchen; 3 sections totaling ₱2,292,000
A17: 15 | B17: Casa Carmelo | C17: Hospitality | D17: La Union | E17: Casa Carmelo 2.0 | F17: LUON012325-1 | G17: Jan 23, 2025 | H17: Fabrication of 3 Open Top Low Pressure Range Stove | I17: 63800 | J17: Quotation Sent | K17: Quotation 2.0 + Revised (DOCX, PDF) | L17: Version 2 with revision
A18: 16 | B18: Chateau De Maisons | C18: Hospitality | D18: Baguio City | E18: Chateau De Maisons | F18: — | G18: August 2025 | H18: Kitchen Equipment Layout Design | I18: See workbook | J18: Design Stage | K18: AutoCAD DWG Plan (Aug 2025) | L18: Design in progress; plan file only
A19: 17 | B19: Chimichanga | C19: Restaurant | D19: Kisad Road, Baguio City | E19: Chimichanga Restaurant | F19: BGON012425-1 | G19: Jan 24, 2025 | H19: Fabrication of Kitchen Equipment | I19: 754600 | J19: Quotation Sent | K19: Quotation (with & without price versions, DOCX + PDF) | L19: Two versions: priced and unpriced
A20: 18 | B20: Cosmos | C20: Food Service | D20: La Union | E20: Cosmos | F20: LUON-07172025-1 | G20: July 17, 2025 | H20: Rotary Oven Repair | I20: 118000 | J20: Quotation Sent | K20: Quotation + Repair Scope (DOCX, PDF, JPG) | L20: Repair/maintenance quotation
A21: 19 | B21: DepEd Baguio | C21: Education / Govt | D21: Baguio City | E21: DepEd – Baguio City | F21: — | G21: Nov 18, 2024 | H21: Supply of School Laboratory Equipment | I21: 1196487 | J21: Won / Ongoing | K21: Market Survey + Quotation + PO-3277 (Narciso) + PO Signed | L21: PO issued; two signed POs on file; active government order
A22: 20 | B22: DMMMSU (Sales) | C22: Education | D22: La Union | E22: DMMMSU | F22: — | G22: 2024 | H22: Kitchen Equipment Supply & Fabrication (Project Portfolio) | I22: See workbook | J22: Completed | K22: Project Portfolio (DOCX) | L22: Government project completed via Biddings; portfolio doc for reference
A23: 21 | B23: El Cielito | C23: Hospitality | D23: 50 North Dr., Baguio City | E23: El Cielito Hotel | F23: BGON07112401 | G23: Nov 7, 2024 | H23: Supply & Installation of Exhaust and Fresh Air System | I23: 1428800 | J23: Quotation Sent | K23: Price Quotation (DOCX) | L23: Ventilation system quotation
A24: 22 | B24: Florante Ponce | C24: Food Service | D24: La Union | E24: Florante Ponce | F24: LUON04112025-1 | G24: April 11, 2025 | H24: Kitchen Fabrication Works | I24: 112350 | J24: Quotation Sent | K24: Quotation 2025-04-11 + Preliminary (DOCX, JPG, PDF) | L24: Formal and preliminary versions
A25: 23 | B25: Hatche Cafe | C25: Café | D25: Baguio City | E25: JC Versoza / Hatche Cafe | F25: BGON09202501 | G25: 2025 | H25: Kitchen Fabrication Setup | I25: 469280 | J25: Quotation Sent | K25: Formal Quotation + Stove Quotation (DOCX, PDF) | L25: Two versions: base ₱419,000 + revised ₱469,280
A26: 24 | B26: Henry | C26: Food Service | D26: Unknown Location | E26: Henry | F26: — | G26: — | H26: Kitchen Equipment | I26: See workbook | J26: Quotation Sent | K26: Quotation (XLSM workbook) | L26: Amount in XLSM workbook
A27: 25 | B27: ITRMC | C27: Hospital | D27: La Union | E27: ITRMC | F27: LUON07062025-1 | G27: Oct 14, 2025 | H27: Supply & Fabrication of Kitchen Equipment | I27: 998000 | J27: Won / Ongoing | K27: Multiple Quotations (Sep–Nov 2025) + PO 2026-01-0040 + Canvas Forms + Site Photos + Job Order | L27: PO 2026-01-0040 issued; signed canvass forms; site photos Dec 2025; multiple quotation revisions
A28: 26 | B28: J&V | C28: Food Service | D28: Unknown Location | E28: J&V | F28: — | G28: — | H28: Kitchen Layout Design | I28: See workbook | J28: Design Stage | K28: AutoCAD DWG Plan + Reference Image | L28: Design phase only; no quotation issued yet
A29: 27 | B29: Jackie Red Ausa | C29: Food Service | D29: Loacan, Itogon, Benguet | E29: Jackie Red Ausa | F29: BGON07012025-1 | G29: July 1, 2025 | H29: Fabrication, Supply & Installation of Kitchen Setup | I29: 1246900 | J29: Quotation Sent | K29: Price Quotation (DOCX, PDF) | L29: Full kitchen setup quotation
A30: 28 | B30: Jessa Sison | C30: Food Service | D30: Vigan, Ilocos Sur | E30: Jessa Sison | F30: — | G30: — | H30: Supply of Armchairs | I30: See workbook | J30: Quotation Sent | K30: Quotation Workbook (XLSM) + Reference Photos | L30: Furniture/armchair quotation; amount in XLSM
A31: 29 | B31: Jomarcann | C31: Food Service | D31: Sta. Cruz, Ilocos Sur | E31: Jomarcann | F31: — | G31: — | H31: Kitchen Equipment Supply & Fabrication | I31: See workbook | J31: Quotation Sent | K31: Quotation PDF + XLSM | L31: Amount in XLSM workbook
A32: 30 | B32: Joms Lano | C32: Food Service | D32: Baguio City | E32: Joms Lano | F32: — | G32: Dec 2024 | H32: Kitchen Equipment & Ducting (Billing + Additionals) | I32: See workbook | J32: Completed | K32: Price Quotation + Billing Invoice + Additionals + Ducting Extension + Final Billing + Range Hood | L32: Completed; billing invoice and final billing PDFs on file; ducting extension added
A33: 31 | B33: Jorence Madio | C33: Food Service | D33: Rodriguez, Rizal | E33: Jorence Madio | F33: — | G33: Aug 25, 2025 | H33: Kitchen Equipment Supply & Fabrication | I33: See workbook | J33: Quotation Sent | K33: Quotation 2025-08-25 (PDF) | L33: PDF only; amount not extractable
A34: 32 | B34: Juan Paolo Prado | C34: Food Service | D34: Makati (Sison Bus Stop) | E34: Juan Paolo Prado | F34: MKON06182025-01 | G34: June 18, 2025 | H34: Fabrication & Installation of Range Hood + Fire Suppression | I34: 942200 | J34: Quotation Sent | K34: Multiple Quotations + Fire Suppression Specs (DOCX, JPG, PDF) | L34: Includes fire suppression system specs
A35: 33 | B35: Jun Tamayo | C35: Food Service | D35: Unknown Location | E35: Jun Tamayo | F35: — | G35: — | H35: BI Sheet Exhaust System & AC Pancake Supply | I35: 690000 | J35: Quotation Sent | K35: Price Quotation + AC Supply Quotation (DOCX, PDF) | L35: Includes ventilation and AC equipment
A36: 34 | B36: Justin Bautista | C36: Food Service | D36: Tondaligan, Bonuan, Pangasinan | E36: Justin Bautista | F36: ONBG0362025-01 | G36: March 26, 2025 | H36: Fabrication of Kitchen Equipment | I36: 557300 | J36: Quotation Sent | K36: Quotation (with & without price versions, DOCX, PDF) | L36: Revised total ₱557,300; base ₱410,000
A37: 35 | B37: Kings College | C37: Education | D37: La Trinidad, Benguet | E37: Kings College | F37: BGON12102401 | G37: Dec 10, 2024 | H37: Fabrication & Repair of Hood and Duct System | I37: 199000 | J37: Quotation Sent | K37: Quotation (DOCX, PDF)
A38: 36 | B38: Lorma Colleges | C38: Education | D38: San Fernando, La Union | E38: Lorma Colleges | F38: — | G38: Aug 1, 2025 | H38: Kitchen Equipment (Preliminary Quotation) | I38: See workbook | J38: Quotation Sent | K38: Preliminary Quotation (XLSX) | L38: Preliminary only; amount in XLSX workbook
A39: 37 | B39: Melrog Matthews | C39: Food Service | D39: Sta. Cruz, Ilocos Sur | E39: Melrog Matthews | F39: — | G39: — | H39: Kitchen Equipment Layout Design | I39: See workbook | J39: Design Stage | K39: Quotation PDF + AutoCAD DWG Plans | L39: AutoCAD design files; detailed floor plan
A40: 38 | B40: Mikee Amlap | C40: Food Service | D40: Unknown Location | E40: Mikee Amlap | F40: BGON-04152025-1 | G40: April 15, 2025 | H40: Food Processing Equipment Supply | I40: 91000 | J40: Quotation Sent | K40: Price Quotation (DOCX) | L40: Estimated from line items
...

Sheet Analytics
A1: CLIENT ANALYTICS — PIPELINE & PERFORMANCE
A3: SALES PIPELINE FUNNEL
A4: STAGE | C4: COUNT | D4: % TOTAL | E4: QUOTED VALUE (₱)
A5: Design Stage | C5: =COUNTIF('Client Records'!J3:J200,"Design Stage") | D5: =IFERROR(C5/COUNTA('Client Records'!A3:A200),"-") | E5: =SUMIF('Client Records'!J3:J200,"Design Stage",'Client Records'!I3:I200)
A6: Quotation Sent | C6: =COUNTIF('Client Records'!J3:J200,"Quotation Sent")+COUNTIF('Client Records'!J3:J200,"Proposal Sent") | D6: =IFERROR(C6/COUNTA('Client Records'!A3:A200),"-") | E6: =SUMIF('Client Records'!J3:J200,"Quotation Sent",'Client Records'!I3:I200)+SUMIF('Client Records'!J3:J200,"Proposal Sent",'Client Records'!I3:I200)
A7: Won / Ongoing | C7: =COUNTIF('Client Records'!J3:J200,"Won / Ongoing")+COUNTIF('Client Records'!J3:J200,"Ongoing") | D7: =IFERROR(C7/COUNTA('Client Records'!A3:A200),"-") | E7: =SUMIF('Client Records'!J3:J200,"Won / Ongoing",'Client Records'!I3:I200)+SUMIF('Client Records'!J3:J200,"Ongoing",'Client Records'!I3:I200)
A8: Completed | C8: =COUNTIF('Client Records'!J3:J200,"Completed") | D8: =IFERROR(C8/COUNTA('Client Records'!A3:A200),"-") | E8: =SUMIF('Client Records'!J3:J200,"Completed",'Client Records'!I3:I200)
A9: Lost / No Response | C9: =COUNTIF('Client Records'!J3:J200,"Lost / No Response") | D9: =IFERROR(C9/COUNTA('Client Records'!A3:A200),"-") | E9: =SUMIF('Client Records'!J3:J200,"Lost / No Response",'Client Records'!I3:I200)
A12: KEY PERFORMANCE METRICS
A13: Win Rate (Won + Ongoing + Completed / Total) | C13: =IFERROR((COUNTIF('Client Records'!J3:J200,"Completed")+COUNTIF('Client Records'!J3:J200,"Won / Ongoing")+COUNTIF('Client Records'!J3:J200,"Ongoing"))/COUNTA('Client Records'!A3:A200),"-")
A14: Quotation-to-Win Conversion | C14: =IFERROR((COUNTIF('Client Records'!J3:J200,"Completed")+COUNTIF('Client Records'!J3:J200,"Won / Ongoing")+COUNTIF('Client Records'!J3:J200,"Ongoing"))/(COUNTIF('Client Records'!J3:J200,"Quotation Sent")+COUNTIF('Client Records'!J3:J200,"Completed")+COUNTIF('Client Records'!J3:J200,"Won / Ongoing")+COUNTIF('Client Records'!J3:J200,"Ongoing")),"-")
A15: Total Quoted Pipeline (₱) | C15: =SUMIF('Client Records'!J3:J200,"Quotation Sent",'Client Records'!I3:I200)+SUMIF('Client Records'!J3:J200,"Design Stage",'Client Records'!I3:I200)
A16: Total Won + Completed Revenue (₱) | C16: =SUMIF('Client Records'!J3:J200,"Completed",'Client Records'!I3:I200)+SUMIF('Client Records'!J3:J200,"Won / Ongoing",'Client Records'!I3:I200)+SUMIF('Client Records'!J3:J200,"Ongoing",'Client Records'!I3:I200)
A17: Active Projects (Won / Ongoing) | C17: =COUNTIF('Client Records'!J3:J200,"Won / Ongoing")+COUNTIF('Client Records'!J3:J200,"Ongoing")
A18: Completed Projects | C18: =COUNTIF('Client Records'!J3:J200,"Completed")
A19: Avg Quotation Value (where amount known) | C19: =IFERROR(AVERAGEIF('Client Records'!J3:J200,"Quotation Sent",'Client Records'!I3:I200),"-")
